<mujoco model="newant">
  <compiler angle="degree" coordinate="local" inertiafromgeom="true"/>
  <option integrator="RK4" timestep="0.01" iterations="1000"/>
  <custom>
    <numeric data="-1.0 0.0 0.55 1.0 0.0 0.0 0.0 0.0 1.0 0.0 -1.0 0.0 -1.0 0.0 1.0 1.0 0.0 0.55 1.0 0.0 0.0 0.0 0.0 1.0 0.0 -1.0 0.0 -1.0 0.0 1.0" name="init_qpos"/>
  </custom>
  <default>
    <joint armature="1" damping="1" limited="true"/>
    <geom condim="3" density="5.0" friction="1 0.5 0.5" margin="0.01"/>
    <default class="ant1">
        <geom contype="1" conaffinity="2" rgba="0.8 0.6 0.4 1"/>
    </default>
    <default class="ant2">
        <geom contype="2" conaffinity="1" rgba="0.4 0.1 0.9 1"/>
    </default>
  </default>
  <asset>
    <texture builtin="gradient" height="100" rgb1="1 1 1" rgb2="0 0 0" type="skybox" width="100"/>
    <texture builtin="flat" height="1278" mark="cross" markrgb="1 1 1" name="texgeom" random="0.01" rgb1="0.8 0.6 0.4" rgb2="0.8 0.6 0.4" type="cube" width="127"/>
    <texture builtin="checker" height="100" name="texplane" rgb1="0 0 0" rgb2="0.8 0.8 0.8" type="2d" width="100"/>
    <material name="MatPlane" reflectance="0.5" shininess="1" specular="1" texrepeat="60 60" texture="texplane"/>
    <material name="geom" texture="texgeom" texuniform="true"/>
  </asset>
  <worldbody>
    <light cutoff="100" diffuse="1 1 1" dir="-0 0 -1.3" directional="true" exponent="1" pos="0 0 1.3" specular=".1 .1 .1"/>
    <geom contype="3" conaffinity="3" condim="3" material="MatPlane" name="floor" pos="0 0 0" rgba="0.8 0.9 0.8 1" size="40 40 40" type="plane"/>
    <!-- Beggining of targets for the agents, change this to modify goal distance -->
    <geom fromto="4 -4 0  4 +4 0" name="player1goal" rgba="0.6 0.0 0.0 1" size=".03" type="cylinder"/>
    <geom fromto="-4 -4 0  -4 +4 0" name="player2goal" rgba="0.6 0.0 0.0 1" size=".03" type="cylinder"/>
    <!-- End of target  -->
    <body name="torso" pos="-1 0 0.75">
      <geom class="ant1" name="torso_geom" pos="0 0 0" size="0.25" rgba="0.8 0.9 0.8 1" type="sphere"/>
      <joint armature="0" damping="0" limited="false" margin="0.01" name="root" pos="0 0 0" range="-30 30" type="free"/>
      <body name="front_left_leg" pos="0 0 0">
        <geom class="ant1" fromto="0.0 0.0 0.0 0.2 0.2 0.0" name="aux_1_geom" rgba="0.8 0.9 0.8 1" size="0.08" type="capsule"/>
        <body name="aux_1" pos="0.2 0.2 0">
          <joint axis="0 0 1" name="hip_1" pos="0.0 0.0 0.0" range="-30 30" type="hinge"/>
          <geom class="ant1" fromto="0.0 0.0 0.0 0.2 0.2 0.0" name="left_leg_geom" rgba="0.8 0.9 0.8 1" size="0.08" type="capsule"/>
          <body pos="0.2 0.2 0">
            <joint axis="-1 1 0" name="ankle_1" pos="0.0 0.0 0.0" range="30 70" type="hinge"/>
            <geom class="ant1" fromto="0.0 0.0 0.0 0.4 0.4 0.0" name="left_ankle_geom" rgba="0.8 0.9 0.8 1" size="0.08" type="capsule"/>
          </body>
        </body>
      </body>
      <body name="front_right_leg" pos="0 0 0">
        <geom class="ant1" fromto="0.0 0.0 0.0 -0.2 0.2 0.0" name="aux_2_geom" rgba="0.8 0.9 0.8 1" size="0.08" type="capsule"/>
        <body name="aux_2" pos="-0.2 0.2 0">
          <joint axis="0 0 1" name="hip_2" pos="0.0 0.0 0.0" range="-30 30" type="hinge"/>
          <geom class="ant1" fromto="0.0 0.0 0.0 -0.2 0.2 0.0" name="right_leg_geom" rgba="0.8 0.9 0.8 1" size="0.08" type="capsule"/>
          <body pos="-0.2 0.2 0">
            <joint axis="1 1 0" name="ankle_2" pos="0.0 0.0 0.0" range="-70 -30" type="hinge"/>
            <geom class="ant1" fromto="0.0 0.0 0.0 -0.4 0.4 0.0" name="right_ankle_geom" rgba="0.8 0.9 0.8 1" size="0.08" type="capsule"/>
          </body>
        </body>
      </body>
      <body name="back_leg" pos="0 0 0">
        <geom class="ant1" fromto="0.0 0.0 0.0 -0.2 -0.2 0.0" name="aux_3_geom" rgba="0.8 0.9 0.8 1" size="0.08" type="capsule"/>
        <body name="aux_3" pos="-0.2 -0.2 0">
          <joint axis="0 0 1" name="hip_3" pos="0.0 0.0 0.0" range="-30 30" type="hinge"/>
          <geom class="ant1" fromto="0.0 0.0 0.0 -0.2 -0.2 0.0" name="back_leg_geom" rgba="0.8 0.9 0.8 1" size="0.08" type="capsule"/>
          <body pos="-0.2 -0.2 0">
            <joint axis="-1 1 0" name="ankle_3" pos="0.0 0.0 0.0" range="-70 -30" type="hinge"/>
            <geom class="ant1" fromto="0.0 0.0 0.0 -0.4 -0.4 0.0" name="third_ankle_geom" rgba="0.8 0.9 0.8 1" size="0.08" type="capsule"/>
          </body>
        </body>
      </body>
      <body name="right_back_leg" pos="0 0 0">
        <geom class="ant1" fromto="0.0 0.0 0.0 0.2 -0.2 0.0" name="aux_4_geom" rgba="0.8 0.9 0.8 1" size="0.08" type="capsule"/>
        <body name="aux_4" pos="0.2 -0.2 0">
          <joint axis="0 0 1" name="hip_4" pos="0.0 0.0 0.0" range="-30 30" type="hinge"/>
          <geom class="ant1" fromto="0.0 0.0 0.0 0.2 -0.2 0.0" name="rightback_leg_geom" rgba="0.8 0.9 0.8 1" size="0.08" type="capsule"/>
          <body pos="0.2 -0.2 0">
            <joint axis="1 1 0" name="ankle_4" pos="0.0 0.0 0.0" range="30 70" type="hinge"/>
            <geom class="ant1" fromto="0.0 0.0 0.0 0.4 -0.4 0.0" name="fourth_ankle_geom" rgba="0.8 0.9 0.8 1" size="0.08" type="capsule"/>
          </body>
        </body>
      </body>
    </body>

    <body name="torso2" pos="1 0 0.75">
      <geom class="ant2" name="torso_geom2" pos="0 0 0" size="0.25" type="sphere"/>
      <joint armature="0" damping="0" limited="false" margin="0.01" name="root2" pos="0 0 0" range="-30 30" type="free"/>
      <body name="front_left_leg2" pos="0 0 0">
        <geom class="ant2" fromto="0.0 0.0 0.0 0.2 0.2 0.0" name="aux_1_geom2" size="0.08" type="capsule"/>
        <body name="aux_1_2" pos="0.2 0.2 0">
          <joint axis="0 0 1" name="hip_1_2" pos="0.0 0.0 0.0" range="-30 30" type="hinge"/>
          <geom class="ant2" fromto="0.0 0.0 0.0 0.2 0.2 0.0" name="left_leg_geom2" size="0.08" type="capsule"/>
          <body pos="0.2 0.2 0">
            <joint axis="-1 1 0" name="ankle_1_2" pos="0.0 0.0 0.0" range="30 70" type="hinge"/>
            <geom class="ant2" fromto="0.0 0.0 0.0 0.4 0.4 0.0" name="left_ankle_geom2" size="0.08" type="capsule"/>
          </body>
        </body>
      </body>
      <body name="front_right_leg2" pos="0 0 0">
        <geom class="ant2" fromto="0.0 0.0 0.0 -0.2 0.2 0.0" name="aux_2_geom2" size="0.08" type="capsule"/>
        <body name="aux_2_2" pos="-0.2 0.2 0">
          <joint axis="0 0 1" name="hip_2_2" pos="0.0 0.0 0.0" range="-30 30" type="hinge"/>
          <geom class="ant2" fromto="0.0 0.0 0.0 -0.2 0.2 0.0" name="right_leg_geom2" size="0.08" type="capsule"/>
          <body pos="-0.2 0.2 0">
            <joint axis="1 1 0" name="ankle_2_2" pos="0.0 0.0 0.0" range="-70 -30" type="hinge"/>
            <geom class="ant2" fromto="0.0 0.0 0.0 -0.4 0.4 0.0" name="right_ankle_geom2" size="0.08" type="capsule"/>
          </body>
        </body>
      </body>
      <body name="back_leg2" pos="0 0 0">
        <geom class="ant2" fromto="0.0 0.0 0.0 -0.2 -0.2 0.0" name="aux_3_geom2" size="0.08" type="capsule"/>
        <body name="aux_3_2" pos="-0.2 -0.2 0">
          <joint axis="0 0 1" name="hip_3_2" pos="0.0 0.0 0.0" range="-30 30" type="hinge"/>
          <geom class="ant2" fromto="0.0 0.0 0.0 -0.2 -0.2 0.0" name="back_leg_geom2" size="0.08" type="capsule"/>
          <body pos="-0.2 -0.2 0">
            <joint axis="-1 1 0" name="ankle_3_2" pos="0.0 0.0 0.0" range="-70 -30" type="hinge"/>
            <geom class="ant2" fromto="0.0 0.0 0.0 -0.4 -0.4 0.0" name="third_ankle_geom2" size="0.08" type="capsule"/>
          </body>
        </body>
      </body>
      <body name="right_back_leg2" pos="0 0 0">
        <geom class="ant2" fromto="0.0 0.0 0.0 0.2 -0.2 0.0" name="aux_4_geom2" size="0.08" type="capsule"/>
        <body name="aux_4_2" pos="0.2 -0.2 0">
          <joint axis="0 0 1" name="hip_4_2" pos="0.0 0.0 0.0" range="-30 30" type="hinge"/>
          <geom class="ant2" fromto="0.0 0.0 0.0 0.2 -0.2 0.0" name="rightback_leg_geom_2" size="0.08" type="capsule"/>
          <body pos="0.2 -0.2 0">
            <joint axis="1 1 0" name="ankle_4_2" pos="0.0 0.0 0.0" range="30 70" type="hinge"/>
            <geom class="ant2" fromto="0.0 0.0 0.0 0.4 -0.4 0.0" name="fourth_ankle_geom_2" size="0.08" type="capsule"/>
          </body>
        </body>
      </body>
    </body>
  </worldbody>
  <actuator>
    <motor ctrllimited="true" ctrlrange="-1.0 1.0" joint="hip_4" gear="150"/>
    <motor ctrllimited="true" ctrlrange="-1.0 1.0" joint="ankle_4" gear="150"/>
    <motor ctrllimited="true" ctrlrange="-1.0 1.0" joint="hip_1" gear="150"/>
    <motor ctrllimited="true" ctrlrange="-1.0 1.0" joint="ankle_1" gear="150"/>
    <motor ctrllimited="true" ctrlrange="-1.0 1.0" joint="hip_2" gear="150"/>
    <motor ctrllimited="true" ctrlrange="-1.0 1.0" joint="ankle_2" gear="150"/>
    <motor ctrllimited="true" ctrlrange="-1.0 1.0" joint="hip_3" gear="150"/>
    <motor ctrllimited="true" ctrlrange="-1.0 1.0" joint="ankle_3" gear="150"/>
    <!-- agent2 here -->
    <motor ctrllimited="true" ctrlrange="-1.0 1.0" joint="hip_4_2" gear="150"/>
    <motor ctrllimited="true" ctrlrange="-1.0 1.0" joint="ankle_4_2" gear="150"/>
    <motor ctrllimited="true" ctrlrange="-1.0 1.0" joint="hip_1_2" gear="150"/>
    <motor ctrllimited="true" ctrlrange="-1.0 1.0" joint="ankle_1_2" gear="150"/>
    <motor ctrllimited="true" ctrlrange="-1.0 1.0" joint="hip_2_2" gear="150"/>
    <motor ctrllimited="true" ctrlrange="-1.0 1.0" joint="ankle_2_2" gear="150"/>
    <motor ctrllimited="true" ctrlrange="-1.0 1.0" joint="hip_3_2" gear="150"/>
    <motor ctrllimited="true" ctrlrange="-1.0 1.0" joint="ankle_3_2" gear="150"/>
  </actuator>
</mujoco>
