<mujoco model="snake">
	<compiler inertiafromgeom="true" angle="degree" coordinate="local" />
  	<custom>
    		<numeric name="frame_skip" data="50" />
  	</custom>
  	<option timestep="0.001" density="4000" viscosity="0.1" collision="predefined" integrator="Euler" iterations="1000">
    		<flag warmstart="disable" />
  	</option>
  	<default>
    		<geom contype='1' conaffinity='1' condim='1' rgba='0.8 0.6 .4 1' />
 	</default>

	<asset>
		<texture name="texgeom" type="cube" builtin="flat" mark="cross" width="127" height="1278" rgb1="0.8 0.6 0.4" rgb2="0.8 0.6 0.4" markrgb="1 1 1" random="0.01" />
		<material name='geom' texture="texgeom" texuniform="true" />
	</asset>

	<worldbody>
		<light diffuse=".2 .2 .2" dir="0 0 -1" pos="0 0 2" />
		<!--light cutoff="100" diffuse="1 1 1" dir="-0 0 -1.3" directional="true" exponent="1" pos="0 0 1.3" specular=".1 .1 .1"/-->
		<geom conaffinity="1" contype="1" pos="0 0 0" size="4 4 0.1" rgba="0.9 0.9 0.9 1" type="plane" />
		<body name="torso" pos="2 -2 0">
			<geom name="torso" type="capsule" fromto="1.0 0 0 0.5 0 0" size="0.1" density="1000" />
      			<joint pos="0 0 0" type="slide" name="slider1" axis="1 0 0" />
      			<joint pos="0 0 0" type="slide" name="slider2" axis="0 1 0" />
      			<joint name="rot" type="hinge" pos="0 0 0" axis="0 0 1" />
      			<body name="mid" pos="0.5 0 0">
        			<geom name="mid" type="capsule" fromto="0 0 0 -0.5 0 0" size="0.1" density="1000" />
        			<joint name="rot2" type="hinge" pos="0 0 0" axis="0 0 1" range="-100 100" limited="true" />
        			<body name="back" pos="-0.5 0 0">
          				<geom name="back" type="capsule" fromto="0 0 0 -0.5 0 0" size="0.1" density="1000" />
          				<joint name="rot3" type="hinge" pos="0 0 0" axis="0 0 1" range="-100 100" limited="true" />
            				<body name="back2" pos="-0.5 0 0">
                				<geom name="back2" type="capsule" fromto="0 0 0 -0.5 0 0" size="0.1" density="1000" />
                				<joint name="rot4" type="hinge" pos="0 0 0" axis="0 0 1" range="-100 100" limited="true" />
                				<body name="back3" pos="-0.5 0 0">
                    					<geom name="back3" type="capsule" fromto="0 0 0 -0.5 0 0" size="0.1" density="1000" />
                    					<joint name="rot5" type="hinge" pos="0 0 0" axis="0 0 1" range="-100 100" limited="true" />
                    					<body name="back4" pos="-0.5 0 0">
                        					<geom name="back4" type="capsule" fromto="0 0 0 -0.5 0 0" size="0.1" density="1000" />
                        					<joint name="rot6" type="hinge" pos="0 0 0" axis="0 0 1" range="-100 100" limited="true" />
                    					</body>
                				</body>
            				</body>
        			</body>
      			</body>
    		</body>

		<geom pos="0 4 0" conaffinity="1" rgba="0.9 0.9 0.9 1" size="4 0.1 0.1" type="box"/>
    		<geom pos="0 -4 0" conaffinity="1" rgba="0.9 0.9 0.9 1" size="4 0.1 0.1" type="box"/>
    		<geom pos="4 0 0" conaffinity="1" rgba="0.9 0.9 0.9 1" size="0.1 4 0.1" type="box"/>
		<geom pos="-4 0 0" conaffinity="1" rgba="0.9 0.9 0.9 1" size="0.1 4 0.1" type="box"/>

		<body name="obstacle_1" pos="0 1 0 ">
			<geom conaffinity="1" contype="1" name="obstacle_1" pos="0 0 0" rgba="0.81 0.02 0.06 1" size=".5 .5 .5" type="box"/>
			<!--geom conaffinity="1" contype="1" name="obstacle_1" pos="0 0 0.3" rgba="1 0 0 1" size="0.5" type="sphere"/-->
		</body>

				 
		<body name="obstacle_2" pos="-1 1 0 ">
			<geom conaffinity="1" contype="1" name="obstacle_2" pos="0 0 0" rgba="0.81 0.02 0.06 1" size=".5 .5 .5" type="box"/>
			<!--geom conaffinity="1" contype="1" name="obstacle_2" pos="0 0 0.2" rgba="1 0 0 1" size="0.3" type="sphere"/-->
		</body>


		<body name="obstacle_3" pos="0 -2 0 ">
			<geom conaffinity="1" contype="1" name="obstacle_3" pos="0 0 0" rgba="0.81 0.02 0.06 1" size=".5 .5 .5" type="box"/>
			<!--geom conaffinity="1" contype="1" name="obstacle_3" pos="0 0 0.3" rgba="1 0 0 1" size="0.5" type="sphere"/-->
		</body>


		<body name="obstacle_4" pos="1 2 0 ">
			<geom conaffinity="1" contype="1" name="obstacle_4" pos="0 0 0" rgba="0.81 0.02 0.06 1" size=".5 .5 .5" type="box"/>
			<!--geom conaffinity="1" contype="1" name="obstacle_4" pos="0 0 0.3" rgba="1 0 0 1" size="0.5" type="sphere"/-->
		</body>

		<body name="goal" pos = "-1 3 0">
			<geom conaffinity="0" contype="0" density="0.00001" rgba="0 1 0 1" size="0.5 0.005 0.2" type="cylinder"/>
		</body>
		
	</worldbody>

	<actuator>
    		<motor joint="rot2" ctrllimited="true" ctrlrange="-50 50" />
    		<motor joint="rot3" ctrllimited="true" ctrlrange="-50 50" />
    		<motor joint="rot4" ctrllimited="true" ctrlrange="-50 50" />
    		<motor joint="rot5" ctrllimited="true" ctrlrange="-50 50" />
    		<motor joint="rot6" ctrllimited="true" ctrlrange="-50 50" />
  	</actuator>
</mujoco>

